<?xml version="1.0"?>
<robot name="bevel">
    <link name="base_link">
        <visual>
            <origin xyz="0.0 0.0 0.0" rpy="0.0 0.0 0.0"/>
            <geometry>
                <sphere radius="0.25"/>
            </geometry>
            <material name="black">
                <color rgba="0.0 0.0 0.0 1.0"/>
            </material> 
        </visual>
    </link>
    <link name="first_link">
        <visual>
            <origin xyz="0.125 0.0 0.0" rpy="0 1.57 0.0"/>
            <geometry>
                <cylinder radius="0.15" length="0.25"/>
            </geometry>
            <material name="black">
                <color rgba="0.0 0.0 0.0 1.0"/>
            </material>            
        </visual>
    </link>
    <joint name="base_joint" type="continuous">
        <parent link="base_link"/>
        <child link="first_link"/>
        <axis xyz="0 1 0"/>
        <origin xyz="0 0 0" rpy="0 0 0"/>
    </joint>
    <link name="for_end_joint">
        <visual>
            <origin xyz="0.75 0.0 0.0" rpy="0.0 0.0 0.0"/>
            <geometry>
                <box size="1.5 4.0 1"/>
            </geometry>
            <material name="white">
                <color rgba="1.0 1.0 1.0 1.0"/>
            </material>
        </visual>
    </link>
    <joint name="rot_joint" type="continuous">
        <parent link="first_link"/>
        <child link="for_end_joint"/>
        <axis xyz="1 0 0"/>
        <origin xyz="0.25 0 0" rpy="0 0 0"/>
    </joint>
    <link name="left_finger">
        <visual>
            <origin xyz=".5 0.0 0.0" rpy="0.0 0.0 0.0"/>
            <geometry>
                <box size="1 0.45 1"/>
            </geometry>
            <material name="white">
                <color rgba="1.0 1.0 1.0 1.0"/>
            </material>
        </visual>
    </link>
    <joint name="left" type="fixed">
        <parent link="for_end_joint"/>
        <child link="left_finger"/>
        <origin xyz="1.5 1.775 0.0" rpy="0.0 0.0 0.0"/>
    </joint>
    <link name="right_finger">
        <visual>
            <origin xyz=".5 0.0 0.0" rpy="0.0 0.0 0.0"/>
            <geometry>
                <box size="1 0.45 1"/>
            </geometry>
            <material name="white">
                <color rgba="1.0 1.0 1.0 1.0"/>
            </material>
        </visual>
    </link>
    <joint name="right" type="fixed">
        <parent link="for_end_joint"/>
        <child link="right_finger"/>
        <origin xyz="1.5 -1.775 0.0" rpy="0.0 0.0 0.0"/>
    </joint>
</robot>

<!-- <?xml version="1.0"?>
<robot name="bevel">

    <!-- BASE -->
    <link name="base_link">
        <visual>
            <geometry>
                <sphere radius="0.1"/>
            </geometry>
            <material name="black">
                <color rgba="0.0 0.0 0.0 1.0"/>
            </material> 
        </visual>
    </link>

    <!-- ARM LINK -->
    <link name="first_link">
        <visual>
            <origin xyz="0.2 0.0 0.0" rpy="0 1.57 0"/>
            <geometry>
                <cylinder radius="0.04" length="0.4"/>
            </geometry>
            <material name="black"/>
        </visual>
    </link>

    <joint name="base_joint" type="continuous">
        <parent link="base_link"/>
        <child link="first_link"/>
        <axis xyz="0 1 0"/>
        <origin xyz="0 0 0"/>
    </joint>

    <!-- PALM -->
    <link name="for_end_joint">
        <visual>
            <origin xyz="0.1 0 0"/>
            <geometry>
                <box size="0.2 0.2 0.1"/>
            </geometry>
            <material name="gray">
                <color rgba="0.6 0.6 0.6 1.0"/>
            </material>
        </visual>
    </link>

    <joint name="rot_joint" type="continuous">
        <parent link="first_link"/>
        <child link="for_end_joint"/>
        <origin xyz="0.4 0 0"/>
        <axis xyz="1 0 0"/>
    </joint>

    <!-- LEFT FINGER -->
    <link name="left_finger">
        <visual>
            <origin xyz="0.4 0 0"/>
            <geometry>
                <box size="0.8 0.05 0.05"/>
            </geometry>
            <material name="white">
                <color rgba="1 1 1 1"/>
            </material>
        </visual>
    </link>

    <joint name="left" type="fixed">
        <parent link="for_end_joint"/>
        <child link="left_finger"/>
        <origin xyz="0.1 0.12 0"/>
    </joint>

    <!-- RIGHT FINGER -->
    <link name="right_finger">
        <visual>
            <origin xyz="0.4 0 0"/>
            <geometry>
                <box size="0.8 0.05 0.05"/>
            </geometry>
            <material name="white">
                <color rgba="1 1 1 1"/>
            </material>
        </visual>
    </link>

    <joint name="right" type="fixed">
        <parent link="for_end_joint"/>
        <child link="right_finger"/>
        <origin xyz="0.1 -0.12 0"/>
    </joint>

</robot> -->